ERROR Internal Server Error: /search/
Traceback (most recent call last):
  File "/usr/local/lib/python3.9/site-packages/django/core/handlers/exception.py", line 55, in inner
    response = get_response(request)
  File "/usr/local/lib/python3.9/site-packages/django/core/handlers/base.py", line 197, in _get_response
    response = wrapped_callback(request, *callback_args, **callback_kwargs)
  File "/app/search/views.py", line 30, in search_view
    return redirect("search_results")
NameError: name 'redirect' is not defined
ERROR Internal Server Error: /search/
Traceback (most recent call last):
  File "/usr/local/lib/python3.9/site-packages/django/core/handlers/exception.py", line 55, in inner
    response = get_response(request)
  File "/usr/local/lib/python3.9/site-packages/django/core/handlers/base.py", line 197, in _get_response
    response = wrapped_callback(request, *callback_args, **callback_kwargs)
  File "/app/search/views.py", line 30, in search_view
    return redirect("search_results")
NameError: name 'redirect' is not defined
ERROR Internal Server Error: /search/
Traceback (most recent call last):
  File "/usr/local/lib/python3.9/site-packages/django/core/handlers/exception.py", line 55, in inner
    response = get_response(request)
  File "/usr/local/lib/python3.9/site-packages/django/core/handlers/base.py", line 197, in _get_response
    response = wrapped_callback(request, *callback_args, **callback_kwargs)
  File "/app/search/views.py", line 31, in search_view
    return redirect("search_results")
  File "/usr/local/lib/python3.9/site-packages/django/shortcuts.py", line 48, in redirect
    return redirect_class(resolve_url(to, *args, **kwargs))
  File "/usr/local/lib/python3.9/site-packages/django/shortcuts.py", line 145, in resolve_url
    return reverse(to, args=args, kwargs=kwargs)
  File "/usr/local/lib/python3.9/site-packages/django/urls/base.py", line 88, in reverse
    return resolver._reverse_with_prefix(view, prefix, *args, **kwargs)
  File "/usr/local/lib/python3.9/site-packages/django/urls/resolvers.py", line 828, in _reverse_with_prefix
    raise NoReverseMatch(msg)
django.urls.exceptions.NoReverseMatch: Reverse for 'search_results' not found. 'search_results' is not a valid view function or pattern name.
ERROR Internal Server Error: /search/
Traceback (most recent call last):
  File "/usr/local/lib/python3.9/site-packages/django/core/handlers/exception.py", line 55, in inner
    response = get_response(request)
  File "/usr/local/lib/python3.9/site-packages/django/core/handlers/base.py", line 197, in _get_response
    response = wrapped_callback(request, *callback_args, **callback_kwargs)
  File "/app/search/views.py", line 31, in search_view
    return redirect("search_results")
  File "/usr/local/lib/python3.9/site-packages/django/shortcuts.py", line 48, in redirect
    return redirect_class(resolve_url(to, *args, **kwargs))
  File "/usr/local/lib/python3.9/site-packages/django/shortcuts.py", line 145, in resolve_url
    return reverse(to, args=args, kwargs=kwargs)
  File "/usr/local/lib/python3.9/site-packages/django/urls/base.py", line 88, in reverse
    return resolver._reverse_with_prefix(view, prefix, *args, **kwargs)
  File "/usr/local/lib/python3.9/site-packages/django/urls/resolvers.py", line 828, in _reverse_with_prefix
    raise NoReverseMatch(msg)
django.urls.exceptions.NoReverseMatch: Reverse for 'search_results' not found. 'search_results' is not a valid view function or pattern name.
